OHLCV/TRADE QLIB INTEGRATION TEST REPORT
==================================================

Test Run Date: 2025-09-18 23:12:03
Total Duration: 1.49s
Success Rate: 0.0%


test_ohlcv_trade_schema.py:
  Status: FAILED
  Duration: 0.60s
  Error: Traceback (most recent call last):
  File "C:\Projects\geckoterminal_collector\test_ohlcv_trade_schema.py", line 438, in <module>
    success = asyncio.run(run_tests())
              ^^^^^^^^^^^^^^^^^^^^^^^^
  File "c:\Projects\geckoterminal_collector\.conda\Lib\asyncio\runners.py", line 190, in run
    return runner.run(main)
           ^^^^^^^^^^^^^^^^
  File "c:\Projects\geckoterminal_collector\.conda\Lib\asyncio\runners.py", line 118, in run
    return self._loop.run_until_complete(task)
           ^^^^^^^^^^^^^^^^^^^^^^^^^^^^^^^^^^^
  File "c:\Projects\geckoterminal_collector\.conda\Lib\asyncio\base_events.py", line 654, in run_until_complete
    return future.result()
           ^^^^^^^^^^^^^^^
  File "C:\Projects\geckoterminal_collector\test_ohlcv_trade_schema.py", line 408, in run_tests
    async with asyncpg.create_pool(
  File "c:\Projects\geckoterminal_collector\.conda\Lib\site-packages\asyncpg\pool.py", line 1004, in __aenter__
    await self._async__init__()
  File "c:\Projects\geckoterminal_collector\.conda\Lib\site-packages\asyncpg\pool.py", line 418, in _async__init__
    await self._initialize()
  File "c:\Projects\geckoterminal_collector\.conda\Lib\site-packages\asyncpg\pool.py", line 445, in _initialize
    await first_ch.connect()
  File "c:\Projects\geckoterminal_collector\.conda\Lib\site-packages\asyncpg\pool.py", line 132, in connect
    self._con = await self._pool._get_new_connection()
                ^^^^^^^^^^^^^^^^^^^^^^^^^^^^^^^^^^^^^^
  File "c:\Projects\geckoterminal_collector\.conda\Lib\site-packages\asyncpg\pool.py", line 517, in _get_new_connection
    con = await self._connect(
          ^^^^^^^^^^^^^^^^^^^^
  File "c:\Projects\geckoterminal_collector\.conda\Lib\site-packages\asyncpg\connection.py", line 2421, in connect
    return await connect_utils._connect(
           ^^^^^^^^^^^^^^^^^^^^^^^^^^^^^
  File "c:\Projects\geckoterminal_collector\.conda\Lib\site-packages\asyncpg\connect_utils.py", line 1049, in _connect
    conn = await _connect_addr(
           ^^^^^^^^^^^^^^^^^^^^
  File "c:\Projects\geckoterminal_collector\.conda\Lib\site-packages\asyncpg\connect_utils.py", line 886, in _connect_addr
    return await __connect_addr(params, True, *args)
           ^^^^^^^^^^^^^^^^^^^^^^^^^^^^^^^^^^^^^^^^^
  File "c:\Projects\geckoterminal_collector\.conda\Lib\site-packages\asyncpg\connect_utils.py", line 934, in __connect_addr
    await connected
asyncpg.exceptions.InvalidPasswordError: password authentication failed for user "postgres"


test_qlib_ohlcv_trade_export.py:
  Status: FAILED
  Duration: 0.44s
  Error: Traceback (most recent call last):
  File "C:\Projects\geckoterminal_collector\test_qlib_ohlcv_trade_export.py", line 558, in <module>
    success = asyncio.run(run_tests())
              ^^^^^^^^^^^^^^^^^^^^^^^^
  File "c:\Projects\geckoterminal_collector\.conda\Lib\asyncio\runners.py", line 190, in run
    return runner.run(main)
           ^^^^^^^^^^^^^^^^
  File "c:\Projects\geckoterminal_collector\.conda\Lib\asyncio\runners.py", line 118, in run
    return self._loop.run_until_complete(task)
           ^^^^^^^^^^^^^^^^^^^^^^^^^^^^^^^^^^^
  File "c:\Projects\geckoterminal_collector\.conda\Lib\asyncio\base_events.py", line 654, in run_until_complete
    return future.result()
           ^^^^^^^^^^^^^^^
  File "C:\Projects\geckoterminal_collector\test_qlib_ohlcv_trade_export.py", line 513, in run_tests
    async with asyncpg.create_pool(
  File "c:\Projects\geckoterminal_collector\.conda\Lib\site-packages\asyncpg\pool.py", line 1004, in __aenter__
    await self._async__init__()
  File "c:\Projects\geckoterminal_collector\.conda\Lib\site-packages\asyncpg\pool.py", line 418, in _async__init__
    await self._initialize()
  File "c:\Projects\geckoterminal_collector\.conda\Lib\site-packages\asyncpg\pool.py", line 445, in _initialize
    await first_ch.connect()
  File "c:\Projects\geckoterminal_collector\.conda\Lib\site-packages\asyncpg\pool.py", line 132, in connect
    self._con = await self._pool._get_new_connection()
                ^^^^^^^^^^^^^^^^^^^^^^^^^^^^^^^^^^^^^^
  File "c:\Projects\geckoterminal_collector\.conda\Lib\site-packages\asyncpg\pool.py", line 517, in _get_new_connection
    con = await self._connect(
          ^^^^^^^^^^^^^^^^^^^^
  File "c:\Projects\geckoterminal_collector\.conda\Lib\site-packages\asyncpg\connection.py", line 2421, in connect
    return await connect_utils._connect(
           ^^^^^^^^^^^^^^^^^^^^^^^^^^^^^
  File "c:\Projects\geckoterminal_collector\.conda\Lib\site-packages\asyncpg\connect_utils.py", line 1049, in _connect
    conn = await _connect_addr(
           ^^^^^^^^^^^^^^^^^^^^
  File "c:\Projects\geckoterminal_collector\.conda\Lib\site-packages\asyncpg\connect_utils.py", line 886, in _connect_addr
    return await __connect_addr(params, True, *args)
           ^^^^^^^^^^^^^^^^^^^^^^^^^^^^^^^^^^^^^^^^^
  File "c:\Projects\geckoterminal_collector\.conda\Lib\site-packages\asyncpg\connect_utils.py", line 934, in __connect_addr
    await connected
asyncpg.exceptions.InvalidPasswordError: password authentication failed for user "postgres"


test_complete_ohlcv_trade_pipeline.py:
  Status: FAILED
  Duration: 0.44s
  Error: Traceback (most recent call last):
  File "C:\Projects\geckoterminal_collector\test_complete_ohlcv_trade_pipeline.py", line 624, in <module>
    success = asyncio.run(run_tests())
              ^^^^^^^^^^^^^^^^^^^^^^^^
  File "c:\Projects\geckoterminal_collector\.conda\Lib\asyncio\runners.py", line 190, in run
    return runner.run(main)
           ^^^^^^^^^^^^^^^^
  File "c:\Projects\geckoterminal_collector\.conda\Lib\asyncio\runners.py", line 118, in run
    return self._loop.run_until_complete(task)
           ^^^^^^^^^^^^^^^^^^^^^^^^^^^^^^^^^^^
  File "c:\Projects\geckoterminal_collector\.conda\Lib\asyncio\base_events.py", line 654, in run_until_complete
    return future.result()
           ^^^^^^^^^^^^^^^
  File "C:\Projects\geckoterminal_collector\test_complete_ohlcv_trade_pipeline.py", line 576, in run_tests
    async with asyncpg.create_pool(
  File "c:\Projects\geckoterminal_collector\.conda\Lib\site-packages\asyncpg\pool.py", line 1004, in __aenter__
    await self._async__init__()
  File "c:\Projects\geckoterminal_collector\.conda\Lib\site-packages\asyncpg\pool.py", line 418, in _async__init__
    await self._initialize()
  File "c:\Projects\geckoterminal_collector\.conda\Lib\site-packages\asyncpg\pool.py", line 445, in _initialize
    await first_ch.connect()
  File "c:\Projects\geckoterminal_collector\.conda\Lib\site-packages\asyncpg\pool.py", line 132, in connect
    self._con = await self._pool._get_new_connection()
                ^^^^^^^^^^^^^^^^^^^^^^^^^^^^^^^^^^^^^^
  File "c:\Projects\geckoterminal_collector\.conda\Lib\site-packages\asyncpg\pool.py", line 517, in _get_new_connection
    con = await self._connect(
          ^^^^^^^^^^^^^^^^^^^^
  File "c:\Projects\geckoterminal_collector\.conda\Lib\site-packages\asyncpg\connection.py", line 2421, in connect
    return await connect_utils._connect(
           ^^^^^^^^^^^^^^^^^^^^^^^^^^^^^
  File "c:\Projects\geckoterminal_collector\.conda\Lib\site-packages\asyncpg\connect_utils.py", line 1049, in _connect
    conn = await _connect_addr(
           ^^^^^^^^^^^^^^^^^^^^
  File "c:\Projects\geckoterminal_collector\.conda\Lib\site-packages\asyncpg\connect_utils.py", line 886, in _connect_addr
    return await __connect_addr(params, True, *args)
           ^^^^^^^^^^^^^^^^^^^^^^^^^^^^^^^^^^^^^^^^^
  File "c:\Projects\geckoterminal_collector\.conda\Lib\site-packages\asyncpg\connect_utils.py", line 934, in __connect_addr
    await connected
asyncpg.exceptions.InvalidPasswordError: password authentication failed for user "postgres"

